Workbook

Sheet Raw Data
A1: Maritime Employment — Non-Major Ports (State-wise) | 2001–2025
A2: State / Maritime Board | B2: 2001 | C2: 2002 | D2: 2003 | E2: 2004 | F2: 2005 | G2: 2006 | H2: 2007 | I2: 2008 | J2: 2009 | K2: 2010 | L2: 2011 | M2: 2012 | N2: 2013 | O2: 2014 | P2: 2015 | Q2: 2016 | R2: 2017 | S2: 2018 | T2: 2019 | U2: 2020 | V2: 2021 | W2: 2022 | X2: 2023 | Y2: 2024 | Z2: 2025
A3: GUJARAT | B3: 2441 | C3: 2441 | D3: 2662 | E3: 2048 | F3: 1816 | G3: 1265 | H3: 1743 | I3: 1718 | J3: 1650 | K3: 1590 | L3: 981 | M3: 1886 | N3: 1814 | O3: 1723 | P3: 1593 | Q3: 1465 | R3: 1327 | S3: 1251 | T3: 1056 | U3: 935 | V3: 803 | W3: 687 | X3: 627 | Y3: 593 | Z3: 523
A4: MAHARASHTRA | B4: 173 | C4: 173 | D4: 173 | E4: 165 | F4: 154 | G4: 154 | H4: 154 | I4: 153 | J4: 130 | K4: 84 | L4: 84 | M4: 158 | N4: 361 | O4: 117 | P4: 111 | Q4: 111 | R4: 50 | S4: 50 | T4: 53 | U4: 87 | V4: 84 | W4: 84 | X4: 354 | Y4: 78 | Z4: 100
A5: GOA | B5: 166 | C5: 166 | D5: 166 | E5: 139 | F5: 139 | G5: 134 | H5: 133 | I5: 146 | J5: 140 | K5: 140 | L5: 141 | M5: 148 | N5: 155 | O5: 144 | P5: 142 | Q5: 150 | R5: 142 | S5: 142 | T5: 136 | U5: 129 | V5: 125 | W5: 158 | X5: 152 | Y5: 154 | Z5: 152
A6: DAMAN & DIU | B6: 22 | C6: 22 | D6: 22 | E6: 22 | F6: 22 | G6: 22 | H6: 22 | I6: 22 | J6: 22 | K6: 22 | L6: 22 | M6: 13 | N6: 10 | O6: 10 | P6: 10 | Q6: 10 | R6: 10 | S6: 16 | T6: 6 | U6: 5 | V6: 5 | W6: 4 | X6: 3 | Y6: 3 | Z6: 3
A7: KARNATAKA | B7: 71 | C7: 71 | D7: 99 | E7: 76 | F7: 105 | G7: 109 | H7: 103 | I7: 55 | J7: 146 | K7: 145 | L7: 145 | M7: 124 | N7: 124 | O7: 124 | P7: 0 | Q7: 60 | R7: 61 | S7: 53 | T7: 53 | U7: 36 | V7: 50 | W7: 51 | X7: 51 | Y7: 42 | Z7: 45
A8: KERALA | B8: 354 | C8: 354 | D8: 316 | E8: 257 | F8: 121 | G8: 121 | H8: 185 | I8: 191 | J8: 175 | K8: 175 | L8: 195 | M8: 136 | N8: 133 | O8: 683 | P8: 674 | Q8: 675 | R8: 63 | S8: 89 | T8: 262 | U8: 271 | V8: 274 | W8: 258 | X8: 220 | Y8: 220 | Z8: 238
A9: TAMIL NADU | B9: 110 | C9: 110 | D9: 110 | E9: 73 | F9: 89 | G9: 68 | H9: 68 | I9: 62 | J9: 60 | K9: 60 | L9: 51 | M9: 56 | N9: 28 | O9: 35 | P9: 19 | Q9: 37 | R9: 30 | S9: 49 | T9: 35 | U9: 35 | V9: 38 | W9: 36 | X9: 34 | Y9: 33 | Z9: 22
A10: PUDUCHERRY | B10: 92 | C10: 92 | D10: 79 | E10: 79 | F10: 75 | G10: 75 | H10: 42 | I10: 33 | J10: 59 | K10: 59 | L10: 66 | M10: 60 | N10: 485 | O10: 485 | P10: 222 | Q10: 178 | R10: 218 | S10: 233 | T10: 245 | U10: 245 | V10: 266 | W10: 266 | X10: 266 | Y10: 266 | Z10: 87
A11: ANDHRA PRADESH | B11: 107 | C11: 107 | D11: 109 | E11: 62 | F11: 66 | G11: 57 | H11: 57 | I11: 69 | J11: 269 | K11: 269 | L11: 269 | M11: 1153 | N11: 1195 | O11: 1195 | P11: 789 | Q11: 789 | R11: 2153 | S11: 2153 | T11: 2278 | U11: 2331 | V11: 7487 | W11: 7412 | X11: 7609 | Y11: 7220 | Z11: 5439
A12: ANDAMAN & NICOBAR Island | B12: 474 | C12: 474 | D12: 477 | E12: 470 | F12: 468 | G12: 452 | H12: 447 | I12: 452 | J12: 454 | K12: 454 | L12: 448 | M12: 422 | N12: 425 | O12: 641 | P12: 647 | Q12: 638 | R12: 623 | S12: 603 | T12: 623 | U12: 623 | V12: 279 | W12: 223 | X12: 371 | Y12: 250 | Z12: 235
A13: Orissa | B13: 0 | C13: 0 | D13: 0 | E13: 0 | F13: 0 | G13: 0 | H13: 0 | I13: 118 | J13: 118 | K13: 118 | L13: 118 | M13: 0 | N13: 367 | O13: 759 | P13: 355 | Q13: 355 | R13: 607 | S13: 485 | T13: 361 | U13: 535 | V13: 534 | W13: 419 | X13: 4347 | Y13: 4345 | Z13: 4883
A14: LAKSHADWEEP | B14: 0 | C14: 0 | D14: 0 | E14: 0 | F14: 0 | G14: 0 | H14: 0 | I14: 0 | J14: 0 | K14: 0 | L14: 0 | M14: 0 | N14: 0 | O14: 111 | P14: 111 | Q14: 0 | R14: 0 | S14: 0 | T14: 0 | U14: 0 | V14: 0 | W14: 0 | X14: 185 | Y14: 177 | Z14: 173
A15: TOTAL | B15: =SUM(B3:B14) -> 4010 | C15: =SUM(C3:C14) -> 4010 | D15: =SUM(D3:D14) -> 4213 | E15: =SUM(E3:E14) -> 3391 | F15: =SUM(F3:F14) -> 3055 | G15: =SUM(G3:G14) -> 2457 | H15: =SUM(H3:H14) -> 2954 | I15: =SUM(I3:I14) -> 3019 | ... Z15: =SUM(Z3:Z14) -> 11900

Sheet Analysis
A1: State-wise Employment Analysis
A2: State | B2: Total (All Years) | C2: Average | D2: Max Year Value | E2: Min Year Value | F2: 2001 | G2: 2025 | H2: % Change (2001→2025)
A3: ='Raw Data'!A3 -> GUJARAT | B3: =SUM('Raw Data'!B3:Z3) -> 36638 | C3: =ROUND(AVERAGE('Raw Data'!B3:Z3),0) -> 1466 | D3: =MAX('Raw Data'!B3:Z3) -> 2662 | E3: =MIN(IF('Raw Data'!B3:Z3>0,'Raw Data'!B3:Z3)) -> 523 | F3: ='Raw Data'!B3 -> 2441 | G3: ='Raw Data'!Z3 -> 523 | H3: =IFERROR((G3-F3)/F3,"N/A") -> -0.78574355
A4: ='Raw Data'!A4 -> MAHARASHTRA | B4: =SUM('Raw Data'!B4:Z4) -> 3395 | C4: =ROUND(AVERAGE('Raw Data'!B4:Z4),0) -> 136 | D4: =MAX('Raw Data'!B4:Z4) -> 361 | E4: =MIN(IF('Raw Data'!B4:Z4>0,'Raw Data'!B4:Z4)) -> 50 | F4: ='Raw Data'!B4 -> 173 | G4: ='Raw Data'!Z4 -> 100 | H4: =IFERROR((G4-F4)/F4,"N/A") -> -0.42196532
A5: ='Raw Data'!A5 -> GOA | B5: =SUM('Raw Data'!B5:Z5) -> 3639 | C5: =ROUND(AVERAGE('Raw Data'!B5:Z5),0) -> 146 | D5: =MAX('Raw Data'!B5:Z5) -> 166 | E5: =MIN(IF('Raw Data'!B5:Z5>0,'Raw Data'!B5:Z5)) -> 125 | F5: ='Raw Data'!B5 -> 166 | G5: ='Raw Data'!Z5 -> 152 | H5: =IFERROR((G5-F5)/F5,"N/A") -> -0.084337349
A6: ='Raw Data'!A6 -> DAMAN & DIU | B6: =SUM('Raw Data'!B6:Z6) -> 350 | C6: =ROUND(AVERAGE('Raw Data'!B6:Z6),0) -> 14 | D6: =MAX('Raw Data'!B6:Z6) -> 22 | E6: =MIN(IF('Raw Data'!B6:Z6>0,'Raw Data'!B6:Z6)) -> 3 | F6: ='Raw Data'!B6 -> 22 | G6: ='Raw Data'!Z6 -> 3 | H6: =IFERROR((G6-F6)/F6,"N/A") -> -0.86363636
A7: ='Raw Data'!A7 -> KARNATAKA | B7: =SUM('Raw Data'!B7:Z7) -> 1999 | C7: =ROUND(AVERAGE('Raw Data'!B7:Z7),0) -> 80 | D7: =MAX('Raw Data'!B7:Z7) -> 146 | E7: =MIN(IF('Raw Data'!B7:Z7>0,'Raw Data'!B7:Z7)) -> 0 | F7: ='Raw Data'!B7 -> 71 | G7: ='Raw Data'!Z7 -> 45 | H7: =IFERROR((G7-F7)/F7,"N/A") -> -0.36619718
A8: ='Raw Data'!A8 -> KERALA | B8: =SUM('Raw Data'!B8:Z8) -> 6640 | C8: =ROUND(AVERAGE('Raw Data'!B8:Z8),0) -> 266 | D8: =MAX('Raw Data'!B8:Z8) -> 683 | E8: =MIN(IF('Raw Data'!B8:Z8>0,'Raw Data'!B8:Z8)) -> 63 | F8: ='Raw Data'!B8 -> 354 | G8: ='Raw Data'!Z8 -> 238 | H8: =IFERROR((G8-F8)/F8,"N/A") -> -0.32768362
A9: ='Raw Data'!A9 -> TAMIL NADU | B9: =SUM('Raw Data'!B9:Z9) -> 1348 | C9: =ROUND(AVERAGE('Raw Data'!B9:Z9),0) -> 54 | D9: =MAX('Raw Data'!B9:Z9) -> 110 | E9: =MIN(IF('Raw Data'!B9:Z9>0,'Raw Data'!B9:Z9)) -> 19 | F9: ='Raw Data'!B9 -> 110 | G9: ='Raw Data'!Z9 -> 22 | H9: =IFERROR((G9-F9)/F9,"N/A") -> -0.8
A10: ='Raw Data'!A10 -> PUDUCHERRY | B10: =SUM('Raw Data'!B10:Z10) -> 4273 | C10: =ROUND(AVERAGE('Raw Data'!B10:Z10),0) -> 171 | D10: =MAX('Raw Data'!B10:Z10) -> 485 | E10: =MIN(IF('Raw Data'!B10:Z10>0,'Raw Data'!B10:Z10)) -> 33 | F10: ='Raw Data'!B10 -> 92 | G10: ='Raw Data'!Z10 -> 87 | H10: =IFERROR((G10-F10)/F10,"N/A") -> -0.054347826
A11: ='Raw Data'!A11 -> ANDHRA PRADESH | B11: =SUM('Raw Data'!B11:Z11) -> 50644 | C11: =ROUND(AVERAGE('Raw Data'!B11:Z11),0) -> 2026 | D11: =MAX('Raw Data'!B11:Z11) -> 7609 | E11: =MIN(IF('Raw Data'!B11:Z11>0,'Raw Data'!B11:Z11)) -> 57 | F11: ='Raw Data'!B11 -> 107 | G11: ='Raw Data'!Z11 -> 5439 | H11: =IFERROR((G11-F11)/F11,"N/A") -> 49.831776
A12: ='Raw Data'!A12 -> ANDAMAN & NICOBAR Island | B12: =SUM('Raw Data'!B12:Z12) -> 11673 | C12: =ROUND(AVERAGE('Raw Data'!B12:Z12),0) -> 467 | D12: =MAX('Raw Data'!B12:Z12) -> 647 | E12: =MIN(IF('Raw Data'!B12:Z12>0,'Raw Data'!B12:Z12)) -> 223 | F12: ='Raw Data'!B12 -> 474 | G12: ='Raw Data'!Z12 -> 235 | H12: =IFERROR((G12-F12)/F12,"N/A") -> -0.50421941
A13: ='Raw Data'!A13 -> Orissa | B13: =SUM('Raw Data'!B13:Z13) -> 18824 | C13: =ROUND(AVERAGE('Raw Data'!B13:Z13),0) -> 753 | D13: =MAX('Raw Data'!B13:Z13) -> 4883 | E13: =MIN(IF('Raw Data'!B13:Z13>0,'Raw Data'!B13:Z13)) -> 0 | F13: ='Raw Data'!B13 -> 0 | G13: ='Raw Data'!Z13 -> 4883 | H13: =IFERROR((G13-F13)/F13,"N/A") -> N/A
A14: ='Raw Data'!A14 -> LAKSHADWEEP | B14: =SUM('Raw Data'!B14:Z14) -> 757 | C14: =ROUND(AVERAGE('Raw Data'!B14:Z14),0) -> 30 | D14: =MAX('Raw Data'!B14:Z14) -> 185 | E14: =MIN(IF('Raw Data'!B14:Z14>0,'Raw Data'!B14:Z14)) -> 0 | F14: ='Raw Data'!B14 -> 0 | G14: ='Raw Data'!Z14 -> 173 | H14: =IFERROR((G14-F14)/F14,"N/A") -> N/A

Sheet Pivot Summary
A1: Pivot Summary — Employment by State & Year
A2: Table 1: Total Employment by State (All Years) | E2: Table 2: Year-wise National Total
A3: Rank | B3: State | C3: Total Employment | E3: Year | F3: Total Employment
A4: 1 | B4: =Analysis!A3 -> GUJARAT | C4: =Analysis!B3 -> 36638 | E4: 2001 | F4: ='Raw Data'!B15 -> 4010
A5: 2 | B5: =Analysis!A4 -> MAHARASHTRA | C5: =Analysis!B4 -> 3395 | E5: 2002 | F5: ='Raw Data'!C15 -> 4010
A6: 3 | B6: =Analysis!A5 -> GOA | C6: =Analysis!B5 -> 3639 | E6: 2003 | F6: ='Raw Data'!D15 -> 4213
A7: 4 | B7: =Analysis!A6 -> DAMAN & DIU | C7: =Analysis!B6 -> 350 | E7: 2004 | F7: ='Raw Data'!E15 -> 3391
A8: 5 | B8: =Analysis!A7 -> KARNATAKA | C8: =Analysis!B7 -> 1999 | E8: 2005 | F8: ='Raw Data'!F15 -> 3055
A9: 6 | B9: =Analysis!A8 -> KERALA | C9: =Analysis!B8 -> 6640 | E9: 2006 | F9: ='Raw Data'!G15 -> 2457
A10: 7 | B10: =Analysis!A9 -> TAMIL NADU | C10: =Analysis!B9 -> 1348 | E10: 2007 | F10: ='Raw Data'!H15 -> 2954
A11: 8 | B11: =Analysis!A10 -> PUDUCHERRY | C11: =Analysis!B10 -> 4273 | E11: 2008 | F11: ='Raw Data'!I15 -> 3019
A12: 9 | B12: =Analysis!A11 -> ANDHRA PRADESH | C12: =Analysis!B11 -> 50644 | E12: 2009 | F12: ='Raw Data'!J15 -> 3223
A13: 10 | B13: =Analysis!A12 -> ANDAMAN & NICOBAR Island | C13: =Analysis!B12 -> 11673 | E13: 2010 | F13: ='Raw Data'!K15 -> 3116
A14: 11 | B14: =Analysis!A13 -> Orissa | C14: =Analysis!B13 -> 18824 | E14: 2011 | F14: ='Raw Data'!L15 -> 2520
A15: 12 | B15: =Analysis!A14 -> LAKSHADWEEP | C15: =Analysis!B14 -> 757 | E15: 2012 | F15: ='Raw Data'!M15 -> 4156
B16: GRAND TOTAL | C16: =SUM(C4:C15) -> 140180 | E16: 2013 | F16: ='Raw Data'!N15 -> 5097
E17: 2014 | F17: ='Raw Data'!O15 -> 6027
E18: 2015 | F18: ='Raw Data'!P15 -> 4673
E19: 2016 | F19: ='Raw Data'!Q15 -> 4468
E20: 2017 | F20: ='Raw Data'!R15 -> 5284
E21: 2018 | F21: ='Raw Data'!S15 -> 5124
E22: 2019 | F22: ='Raw Data'!T15 -> 5108
E23: 2020 | F23: ='Raw Data'!U15 -> 5232
E24: 2021 | F24: ='Raw Data'!V15 -> 9945
E25: 2022 | F25: ='Raw Data'!W15 -> 9598
E26: 2023 | F26: ='Raw Data'!X15 -> 14219
E27: 2024 | F27: ='Raw Data'!Y15 -> 13381
E28: 2025 | F28: ='Raw Data'!Z15 -> 11900

Sheet Dashboard
A1: 🚢 MARITIME EMPLOYMENT DASHBOARD | Non-Major Ports | 2001 – 2025
A4: Total Employment 2025 | E4: Total Employment 2001 | I4: Top State in 2025 | M4: States / Boards Tracked
A5: ='Raw Data'!Z15 -> 11900 | E5: ='Raw Data'!B15 -> 4010 | I5: =INDEX('Raw Data'!A3:A14,MATCH(MAX('Raw Data'!Z3:Z14),'Raw Data'!Z3:Z14,0)) -> ANDHRA PRADESH | M5: =12 -> 12
A32: Source: Ministry of Ports, Shipping & Waterways, Government of India | Data covers Non-Major Ports only

Sheet Charts
A1: 📊 CHARTS SHEET — Maritime Employment, Non-Major Ports India (2001–2025)
A3: Chart 1 — State-wise Employment (2025) | L3: Chart 2 — National Employment Trend (2001–2025)
A4: Which states employ the most people at non-major ports today? | L4: How has total employment across all states changed over 25 years?
A28: Chart 3 — State Share of Total Employment (2025) | L28: Chart 4 — Top 3 States: Employment Trend (2001–2025)
A29: Which states dominate employment? Concentration at a glance. | L29: Andhra Pradesh's rise, Odisha's emergence, Gujarat's decline — side by side.
A56: Source: Ministry of Ports, Shipping & Waterways, GoI | All charts based on Non-Major Ports employment data | Built with Microsoft Excel
A80: GUJARAT | B80: 523 | D80: 2001 | E80: 4010
A81: MAHARASHTRA | B81: 100 | D81: 2002 | E81: 4010
A82: GOA | B82: 152 | D82: 2003 | E82: 4213
A83: DAMAN & DIU | B83: 3 | D83: 2004 | E83: 3391
A84: KARNATAKA | B84: 45 | D84: 2005 | E84: 3055
A85: KERALA | B85: 238 | D85: 2006 | E85: 2457
A86: TAMIL NADU | B86: 22 | D86: 2007 | E86: 2954
A87: PUDUCHERRY | B87: 87 | D87: 2008 | E87: 3019
A88: ANDHRA PRADESH | B88: 5439 | D88: 2009 | E88: 3223
A89: ANDAMAN & NIC. | B89: 235 | D89: 2010 | E89: 3116
A90: ODISHA | B90: 4883 | D90: 2011 | E90: 2520
A91: LAKSHADWEEP | B91: 173 | D91: 2012 | E91: 4156
D92: 2013 | E92: 5097
D93: 2014 | E93: 6027
D94: 2015 | E94: 4673
D95: 2016 | E95: 4468
D96: 2017 | E96: 5284
D97: 2018 | E97: 5124
D98: 2019 | E98: 5108
D99: 2020 | E99: 5232
D100: 2021 | E100: 9945
D101: 2022 | E101: 9598
D102: 2023 | E102: 14219
D103: 2024 | E103: 13381
D104: 2025 | E104: 11900
A108: ANDHRA PRADESH | B108: 5439
A109: ODISHA | B109: 4883
A110: GUJARAT | B110: 523
A111: KERALA | B111: 238
A112: ANDAMAN & NIC. | B112: 235
A113: GOA | B113: 152
A114: LAKSHADWEEP | B114: 173
A115: Others | B115: 257
E119: Andhra Pradesh | F119: Odisha | G119: Gujarat
...

Sheet Insights
A1: Key Insights & Commentary — Maritime Employment, Non-Major Ports (2001–2025)
A2: # | B2: State / Area | C2: Key Finding | D2: Metric 1 Label | E2: Metric 1 Value | F2: Metric 2
A3: 📈 GROWTH STORIES — States That Surged
A4: 01 | B4: ANDHRA PRADESH | C4: Most dramatic growth story in this dataset. Employment was a tiny 107 in 2001, exploded to a peak of 7,609 in 2023 — a nearly 50x increase — driven by rapid port infrastructure expansion in the state. | D4: 2001 → 2025 | E4: 107 → 5,439 | F4: 7,609
A5: 02 | B5: ODISHA (Orissa) | C5: Had zero reported employment in 2001–2007, then grew steadily. By 2023–2025 it became the 2nd largest employer with 4,347–4,883 jobs — a rise from nothing to a major maritime hub in under 20 years. | D5: 2008 (first) | E5: 118 jobs | F5: 4,883
A6: 03 | B6: PUDUCHERRY | C6: Employment was stable at ~75–92 through early 2000s, then jumped sharply to 485 in 2013–2014 before settling. Suggests a major new port activity or registration in that period. | D6: 2001 | E6: 92 jobs | F6: 485
A7: 📉 DECLINE STORIES — States That Contracted
A8: 04 | B8: GUJARAT | C8: The biggest decline in absolute terms. Was the top employer in 2001 with 2,441 jobs but fell consistently to just 523 in 2025 — a 79% drop. Likely reflects shift of cargo activity to JNPT (major port) or changing fleet registration patterns. | D8: 2001 | E8: 2,441 jobs | F8: −78.6%
A9: 05 | B9: DAMAN & DIU | C9: Employment has been near-extinct since the mid-2010s, from 22 in 2001 down to just 3 in 2025. Small union territory with very limited maritime activity today. | D9: 2001 | E9: 22 jobs | F9: 3 jobs
A10: 06 | B10: TAMIL NADU | C10: Steady decline from 110 in 2001 to only 22 in 2025. Despite being a large coastal state, non-major port employment has shrunk significantly — major ports like Chennai dominate. | D10: 2001 | E10: 110 jobs | F10: 22 jobs
A11: 🔄 NATIONAL TRENDS — Big Picture
A12: 07 | B12: Overall Growth | C12: National total grew from 4,010 in 2001 to a peak of 14,219 in 2023 — a 255% increase. However, most of this growth is concentrated in just 2 states: Andhra Pradesh and Odisha. | D12: 2001 Total | E12: 4,010 | F12: 14,219
A13: 08 | B13: Post-2023 Dip | C13: After peaking at 14,219 in 2023, total employment fell to 11,900 in 2025 — a 16% drop in just 2 years. This aligns with Andhra Pradesh's own decline from 7,609 (2023) to 5,439 (2025). | D13: 2023 Peak | E13: 14,219 | F13: 11,900
A14: 09 | B14: Concentration Risk | C14: Andhra Pradesh alone accounts for ~46% of total 2025 employment. This over-reliance on a single state means national totals are highly sensitive to AP's policy and port activity changes. | D14: AP share 2025 | E14: ~46% | F14: Only 3
A15: 10 | B15: Stable Mid-tier | C15: GOA and Kerala have maintained relatively stable employment (~130–200 range) through the entire 25-year period, suggesting consistent small-scale port activity independent of the boom-bust cycles elsewhere. | D15: Goa 2001 | E15: 166 | F15: 152
A17: Source: Ministry of Ports, Shipping & Waterways, Government of India | Analysis covers Non-Major Ports only | All figures represent direct employment

Sheet Forecast
A1: Employment Trend Forecast — Non-Major Ports (2026–2030)
A2: State / Maritime Board | B2: 2016 | C2: 2017 | D2: 2018 | E2: 2019 | F2: 2020 | G2: 2021 | H2: 2022 | I2: 2023 | J2: 2024 | K2: 2025 | L2: 2026 (Forecast) | M2: 2027 (Forecast) | N2: 2028 (Forecast) | O2: 2029 (Forecast) | P2: 2030 (Forecast)
A3: GUJARAT | B3: 1465 | C3: 1327 | D3: 1251 | E3: 1056 | F3: 935 | G3: 803 | H3: 687 | I3: 627 | J3: 593 | K3: 523 | L3: 328 | M3: 219 | N3: 110 | O3: 1 | P3: 0
A4: MAHARASHTRA | B4: 111 | C4: 50 | D4: 50 | E4: 53 | F4: 87 | G4: 84 | H4: 84 | I4: 354 | J4: 78 | K4: 100 | L4: 162 | M4: 172 | N4: 183 | O4: 193 | P4: 203
A5: GOA | B5: 150 | C5: 142 | D5: 142 | E5: 136 | F5: 129 | G5: 125 | H5: 158 | I5: 152 | J5: 154 | K5: 152 | L5: 151 | M5: 152 | N5: 154 | O5: 155 | P5: 156
A6: DAMAN & DIU | B6: 10 | C6: 10 | D6: 16 | E6: 6 | F6: 5 | G6: 5 | H6: 4 | I6: 3 | J6: 3 | K6: 3 | L6: 0 | M6: 0 | N6: 0 | O6: 0 | P6: 0
A7: KARNATAKA | B7: 60 | C7: 61 | D7: 53 | E7: 53 | F7: 36 | G7: 50 | H7: 51 | I7: 51 | J7: 42 | K7: 45 | L7: 41 | M7: 40 | N7: 38 | O7: 36 | P7: 35
A8: KERALA | B8: 675 | C8: 63 | D8: 89 | E8: 262 | F8: 271 | G8: 274 | H8: 258 | I8: 220 | J8: 220 | K8: 238 | L8: 184 | M8: 171 | N8: 158 | O8: 144 | P8: 131
A9: TAMIL NADU | B9: 37 | C9: 30 | D9: 49 | E9: 35 | F9: 35 | G9: 38 | H9: 36 | I9: 34 | J9: 33 | K9: 22 | L9: 29 | M9: 28 | N9: 27 | O9: 25 | P9: 24
A10: PUDUCHERRY | B10: 178 | C10: 218 | D10: 233 | E10: 245 | F10: 245 | G10: 266 | H10: 266 | I10: 266 | J10: 266 | K10: 87 | L10: 219 | M10: 218 | N10: 216 | O10: 215 | P10: 214
A11: ANDHRA PRADESH | B11: 789 | C11: 2153 | D11: 2153 | E11: 2278 | F11: 2331 | G11: 7487 | H11: 7412 | I11: 7609 | J11: 7220 | K11: 5439 | L11: 8659 | M11: 9418 | N11: 10176 | O11: 10935 | P11: 11693
A12: ANDAMAN & NICOBAR Island | B12: 638 | C12: 623 | D12: 603 | E12: 623 | F12: 623 | G12: 279 | H12: 223 | I12: 371 | J12: 250 | K12: 235 | L12: 149 | M12: 95 | N12: 40 | O12: 0 | P12: 0
A13: Orissa | B13: 355 | C13: 607 | D13: 485 | E13: 361 | F13: 535 | G13: 534 | H13: 419 | I13: 4347 | J13: 4345 | K13: 4883 | L13: 4567 | M13: 5091 | N13: 5614 | O13: 6138 | P13: 6662
A14: LAKSHADWEEP | B14: 0 | C14: 0 | D14: 0 | E14: 0 | F14: 0 | G14: 0 | H14: 0 | I14: 185 | J14: 177 | K14: 173 | L14: 178 | M14: 200 | N14: 223 | O14: 245 | P14: 268
A15: TOTAL | B15: 4468 | C15: 5284 | D15: 5124 | E15: 5108 | F15: 5232 | G15: 9945 | H15: 9598 | I15: 14219 | J15: 13381 | K15: 11900 | L15: 14667 | M15: 15804 | N15: 16939 | O15: 18087 | P15: 19386
A17: ⚠ Methodology: Forecasts use Linear Regression (FORECAST.LINEAR equivalent) based on 2016–2025 actuals. Forecast values are directional estimates only — actual figures depend on policy, infrastructure investment, and port activity.
A19: Year | B19: Historical | C19: Forecast
A20: 2016 | B20: 4468
A21: 2017 | B21: 5284
A22: 2018 | B22: 5124
A23: 2019 | B23: 5108
A24: 2020 | B24: 5232
A25: 2021 | B25: 9945
A26: 2022 | B26: 9598
A27: 2023 | B27: 14219
A28: 2024 | B28: 13381
A29: 2026 | B29: 11900 | C29: 14667
A30: 2027 | C30: 15804
A31: 2028 | C31: 16939
A32: 2029 | C32: 18087
A33: 2030 | C33: 19386
